<robot name="mycar">  

  <link name="base_link">  
    <visual>  
       <geometry>  
          <cylinder length="0.19" radius="0.25"></cylinder>  
       </geometry>  
       <origin rpy="0 0 0" xyz="0 0 0.095"/>  
       <material name="white">  
         <color rgba="1 1 1 1"/>  
       </material>  
    </visual>  
  </link>  
  
  <link name="base_footprint"/>

  <joint name="base_joint" type="fixed">
    <parent link="base_footprint"/>
    <child link="base_link" />
    <origin xyz="0 0 0.010" rpy="0 0 0"/>
  </joint>

  <link name="right">  
    <visual>  
      <geometry>  
        <cylinder length="0.04" radius="0.08"/>  
      </geometry>  
      <origin rpy="1.5707  0  0" xyz="0 0 0.08"/>  
      <material name="black">  
        <color rgba="0 0 0 1"/>  
      </material>  
    </visual>  
  </link>  
  
  <link name="left">  
    <visual>  
      <geometry>  
        <cylinder length="0.04" radius="0.08"/>  
      </geometry>  
      <origin rpy="1.5707  0  0" xyz="0 0 0.08"/>  
      <material name="black"/>  
    </visual>  
  </link>  
  
  <joint name="right" type="continuous"> 
    <origin rpy="0  0  0" xyz="0 -0.204 -0.015"/>   
    <parent link="base_link"/>  
    <child link="right"/>  
  </joint>  
  
  <joint name="left" type="continuous">  
    <origin rpy="0 0 0" xyz="0 0.204 -0.015"/>
    <parent link="base_link"/>  
    <child link="left"/>   
  </joint>  
 
  <link name="imu_link">
    <visual>
      <origin xyz="0 0 0" />
      <geometry>
        <box size="0.06 0.04 0.02" />
      </geometry>
      <material name="orange" />
    </visual>
  </link>

  <joint name="imu_link_joint" type="fixed">
    <parent link="base_link" />
    <child link="imu_link" />
    <origin xyz="0 0 0.19" />
  </joint>


 <link name="laser_frame">
    <inertial>
      <mass value="1e-5"/>
      <!-- <origin rpy="0 0 0" xyz="0.173 0 0.205"/> -->
      <!-- cali num -->
      <origin rpy="0 0 0" xyz="0 0 0"/>
      <inertia ixx="1e-6" ixy="0" ixz="0" iyy="1e-6" iyz="0" izz="1e-6"/>
    </inertial>
    <collision>
      <origin rpy="0 0 0" xyz="0 0 0"/>
      <geometry>
        <cylinder length="0.04" radius="0.035"></cylinder>  
      </geometry>
    </collision>
  </link>
  <joint name="laser_frame_joint" type="fixed">
    <axis xyz="0 1 0"/>
    <!-- <origin  xyz="0.173 0 0.205"/> -->
    <!-- cali num -->
    <origin rpy="0 0 0" xyz="0.173 0 0"/>
    <parent link="base_link"/>
    <child link="laser_frame"/>
  </joint>

<!-- ultrasonic -->
  <link name="ultrasonic_link_1">
  </link>
  
 <joint name="ultrasonic_joint_1" type="continuous">
    <parent link="base_link"/>
    <child link="ultrasonic_link_1"/>
    <origin rpy="0 0 0"  xyz="0.254 0 0.293" />
  </joint>

<!--  -->
  <link name="ultrasonic_link_2">
  </link>

  <joint name="ultrasonic_link_2_joint" type="fixed">
    <parent link="base_link" />
    <child link="ultrasonic_link_2" />
    <origin rpy="0 0 1.0471975512" xyz="0.127 0.219970 0.293"/>
  </joint>


  <!--  -->
  <link name="ultrasonic_link_3">
  </link>

  <joint name="ultrasonic_link_3_joint" type="fixed">
    <parent link="base_link" />
    <child link="ultrasonic_link_3" />
    <origin rpy="0 0 2.09439510239" xyz="-0.127 0.219970452561 0.293"/>
  </joint>

    <!--  -->
  <link name="ultrasonic_link_4">
  </link>

  <joint name="ultrasonic_link_4_joint" type="fixed">
    <parent link="base_link" />
    <child link="ultrasonic_link_4" />
    <origin rpy="0 0 3.14159265359" xyz="-0.254 0 0.293"/>
  </joint>

  <!--  -->
  <link name="ultrasonic_link_5">
  </link>

  <joint name="ultrasonic_link_5_joint" type="fixed">
    <parent link="base_link" />
    <child link="ultrasonic_link_5" />
    <origin rpy="0 0 4.18879020479" xyz="-0.127 -0.219970452561 0.293"/>
  </joint>

    <!--  -->
  <link name="ultrasonic_link_6">
  </link>

  <joint name="ultrasonic_link_6_joint" type="fixed">
    <parent link="base_link" />
    <child link="ultrasonic_link_6" />
    <origin rpy="0 0 5.23598775598" xyz="0.127 -0.219970452561 0.293"/>
  </joint>        

</robot>  
